Workbook

Sheet جدول رقم 1
A2: Al Jomaih Holding Company
A3: Schedule No.3
A4: Guidelines for filling the Cash Flow Statements (2021 - 2022)
A6: No | B6: Note | C6: Description
A7: 1 | B7: ='جدول رقم 2'!B10 -> Cash Available - Beginning Balance | C7: Represents the actual cash/bank available balance at 1-1-2021
A8: 2 | B8: ='جدول رقم 2'!B15 -> Collection received from Sale of Goods/Services in trade (Cash and Credit) | C8: Represents the receipt of inflows for any sale transaction made to the items the company sells to trade or consumers for the major business line of the company such as (Finished Goods, Cars, Repair service, etc…)
A9: 3 | B9: ='جدول رقم 2'!B16 -> Interest on deposits on local investment made by the Entity | C9: Represents the periodic receipt of inflows for current invested financial instrument that the company owns and recorded in its financial records, which may be like shares, bonds, government securities, or interest on deposits in bank accounts that entity has and recorded in its financials
A10: 4 | B10: ='جدول رقم 2'!B17 -> Other Collection made from Operating Activities | C10: Represents receipt of inflows for the below examples: Cash receipts from lawsuit settlements Cash receipts from insurance companies Cash receipts from licensees Cash receipts from rent Others: please specify
A11: 5 | B11: ='جدول رقم 2'!B20 -> Collection from Sale of Fixed Assets and long term assets | C11: Represents the receipt of inflows for selling any kind of a company's fixed assets and long term investments in bonds or selling of copyright, franchise, goodwill, trademark, and software
A12: 6 | B12: Collection from Sale of Investment (shares, securities or other investments) | C12: Represents the receipt of inflows for selling any financial instrument in full or partially that the company owns and recorded in its financial records, which may be like shares, bonds, government securities, etc…
A13: 7 | B13: ='جدول رقم 2'!B24 -> Collection - Proceeds from short-term or long-term debt | C13: The cash inflow out of a borrowing that company lend to other companies (including sister companies) basis on an agreed terms of repayment within one year or more
A14: 8 | B14: ='جدول رقم 2'!B34 -> Payments to Suppliers (Goods and Services) | C14: Represents all type of payments made to vendors for purchase of raw and packaging materials, finished goods, spare parts and services such as transportation, utilities, insurance, customs, etc…
A15: 9 | B15: ='جدول رقم 2'!B35 -> Payments to Payroll Activities (Wages, Commission, Incentive, etc) | C15: Represents all type of payments made to the employees of the company such the employee benefits and related costs (salaries, transportation, housing, commission, incentive, etc…) and paid on behalf of the employee to external parties (ex. outsourced companies, GOSI, medical insurance, training, etc...)
A16: 10 | B16: ='جدول رقم 2'!B36 -> Tax Payments | C16: Represents all type of payments made to GAZT (ex. Excise tax, withholding tax, VAT, Zakat, etc…)
A17: 11 | B17: ='جدول رقم 2'!B37 -> Payments for Governmental Institutions | C17: Represents all type of payments made to governmental institutions other than GAZT and Social Security (Ex. Labor office, CCP, Ministries, etc…)
A18: 12 | B18: ='جدول رقم 2'!B41 -> Payments for Purchase of Fixed Assets and long term assets | C18: Represents all payments made to purchase any kind of a company's fixed assets and long term investments in bonds or buying copyright, franchise, goodwill, trademark, and software
A19: 13 | B19: ='جدول رقم 2'!B42 -> Payments for Purchase of shares, securties and current/new investments | C19: Represents the payments made to purchase any financial instrument in full or partially that the company owns and records in its financial records, which may be like shares, bonds, government securities, etc…
A20: 14 | B20: Payments for Murabaha Loans | C20: Represents the payments made to settle loan instalment/s as per the agreement made between the company and the bank or any other external party
A21: 15 | B21: Dividend Payments | C21: Only applicable to Al Jomaih Holding (Riyadh) to fill
A22: 16 | B22: ='جدول رقم 2'!B47 -> Payments for Shareholders | C22: Represents any payment made to any of the shareholders in person by the company
A24: General Note: If any of the above cashflow notes are not applicable for our good company, please fill the associated fields with Zero amounts

Sheet جدول رقم 2
B1: Al Jomaih Holding Company | Q1: شركة الجميح القابضة
B2: Schedule No.1 | Q2: جدول رقم (1)
B3: Cash Flow Statement for 2022 | Q3: قائمة التدفقات النقدية عن السنة المالية 2202
B4: Entity Name: | C4: Holding | Q4: اسم الشركة:
D6: Actual | E6: Actual | F6: Actual | G6: Actual | H6: Actual | I6: Actual | J6: Actual | K6: Actual | L6: Actual | M6: Projected | N6: Projected | O6: Projected | P6: Projected
D7: الفعلي | E7: الفعلي | F7: الفعلي | G7: الفعلي | H7: الفعلي | I7: الفعلي | J7: الفعلي | K7: الفعلي | L7: الفعلي | M7: المتوقع | N7: المتوقع | O7: المتوقع | P7: المتوقع
B8: Amount in SR المبالغ بالريال السعودي | C8: Note | D8: 44927 | E8: 44958 | F8: 44986 | G8: 45017 | H8: 45047 | I8: 45078 | J8: 45108 | K8: 45139 | L8: 45170 | M8: 45200 | N8: 45231 | O8: 45261 | P8: Full Year
C9: التفصيل | D9: يناير 23 | E9: فبراير 23 | F9: مارس 23 | G9: ابريل 23 | H9: مايو 23 | I9: يونيو 23 | J9: يوليو 23 | K9: أغسطس 23 | L9: سبتمبر 23 | M9: أكتوبر 23 | N9: نوفمبر 23 | O9: ديسمبر 23 | P9: كل العام
B10: Cash Available - Beginning Balance | C10: 1 | D10: 60636405 | E10: =D53 -> 68653994 | F10: =E53 -> 55812705 | G10: =F53 -> 61572808 | H10: =G53 -> 61572808 | I10: =H53 -> 61572808 | J10: =I53 -> 61572808 | K10: =J53 -> 61572808 | L10: =K53 -> 61572808 | ... O10: =N53 -> 61572808 | P10: =D10 -> 60636405 | Q10: النقد المتاح في بداية الفترة
B12: Cash Inflow | Q12: التدفقات النقدية الواردة:
B14: A) Cash from Operating Activities | Q14: أ) التدفقات النقدية من الأنشطة التشغيلية
B15: Collection received from Sale of Goods/Services in trade (Cash and Credit) | C15: 2 | D15: 95996 | E15: 5096467.1 | F15: 3267486.2 | G15: 0 | H15: 0 | I15: 0 | J15: 0 | K15: 0 | L15: 0 | M15: 0 | N15: 0 | O15: 0 | P15: =SUM(D15:O15) -> 8459949.3 | Q15: المتحصلات من المبيعات للبضائع والخدمات ( النقد والذمم المدينة )
B16: Interest on deposits on local investment made by the Entity | C16: 3 | D16: 2351495 | E16: 12604036 | F16: 50147431 | G16: 0 | H16: 0 | I16: 0 | J16: 0 | K16: 0 | L16: 0 | M16: 0 | N16: 0 | O16: 0 | P16: =SUM(D16:O16) -> 65102962 | Q16: الفوائد المحصلة من الودائع أو أرباح من الاستثمارات محلية تمت عن طريق الشركة
B17: Other Collection made from Operating Activities | C17: 4 | D17: 0 | E17: 0 | F17: 0 | G17: 0 | H17: 0 | I17: 0 | J17: 0 | K17: 0 | L17: 0 | M17: 0 | N17: 0 | O17: 0 | P17: =SUM(D17:O17) -> 0 | Q17: متحصلات أخرى من الأنشطة التشغيلية
B19: B) Cash from Investing Activities | Q19: ب) التدفقات النقدية من الأنشطة الإستثمارية
B20: Collection from Sale of Fixed Assets and long term assets | C20: 5 | P20: =SUM(D20:O20) -> 0 | Q20: التحصيلات النقدية من بيع الموجودات الثابتة أو بيع أصول طويلة الاجل
B21: Collection from Sale of Investment (shares, securties or other investments) | C21: 6 | D21: 0 | E21: 0 | F21: 0 | G21: 0 | H21: 0 | I21: 0 | J21: 0 | K21: 0 | L21: 0 | M21: 0 | N21: 0 | O21: 0 | P21: =SUM(D21:O21) -> 0 | Q21: التحصيلات من الاستثمارات التي تمت في أسهم، سندات أو استثمارات خارجية تمت عن طريق الشركة
B23: C) Cash from Financing Activities | Q23: س) التدفقات النقدية من الأنشطة التمويلية
B24: Collection - Proceeds from short-term or long-term debt | C24: 7 | D24: 0 | E24: 0 | F24: 0 | G24: 0 | H24: 0 | I24: 0 | L24: 0 | M24: 0 | P24: =SUM(D24:O24) -> 0 | Q24: التحصيلات من القروض القصيرة أو طويلة الاجل تم منحها الى أطراف خارجية
B25: Collection - Proceeds from issue of shares "Investment" | D25: Not Applicable غير مطبقة في الشركة القابضة والشركات التابعة لها | P25: =SUM(D25:O25) -> 0 | Q25: التحصيلات للعوائد من اصدار أسهم قامت بإصدارها الشركة
B26: long term loan | G26: 0 | I26: 0 | M26: 0 | O26: 0 | Q26: قروض طويلة الاجل
B27: D) Collection from Related-Affiliated Parties | D27: =(6800000+545787692) -> 552587692 | E27: =(1074573.8+221796819.81) -> 2.2287139e+08 | F27: =(3000000+333389569.75) -> 3.3638957e+08 | G27: 0 | H27: 0 | I27: 0 | J27: 0 | K27: 0 | L27: 0 | M27: 0 | N27: 0 | O27: 0 | P27: =SUM(D27:O27) -> 1.1118487e+09 | Q27: د) المتحصلات من الشركات الشقيقة التابعه
B29: Total Cash Inflow | D29: =SUM(D15:D28) -> 555035183 | E29: =SUM(E15:E28) -> 2.405719e+08 | F29: =SUM(F15:F28) -> 389804487 | G29: =SUM(G15:G28) -> 0 | H29: =SUM(H15:H28) -> 0 | I29: =SUM(I15:I28) -> 0 | J29: =SUM(J15:J28) -> 0 | K29: =SUM(K15:K28) -> 0 | ... P29: =SUM(P15:P28) -> 1.1854116e+09 | Q29: اجمالي التدفقات النقدية الواردة :
B31: Cash Outflow | Q31: التدفقات النقدية الصادرة:
B33: A) Cash for Operating Activities | Q33: أ) التدفقات النقدية من الأنشطة التشغيلية
B34: Payments to Suppliers (Goods and Services) | D34: -19882972 | E34: -7285868.3 | F34: -13700308 | G34: 0 | H34: 0 | I34: 0 | J34: 0 | K34: 0 | L34: 0 | M34: 0 | N34: 0 | O34: 0 | P34: =SUM(D34:O34) -> -40869148 | Q34: المدفوعات للموردين (البضائع والخدمات )
B35: Payments to Payroll Activities (Wages, Commission, Incentive, etc) | D35: -2972007 | E35: -2125766 | F35: -2321023.2 | G35: 0 | H35: 0 | I35: 0 | J35: 0 | K35: 0 | L35: 0 | M35: 0 | N35: 0 | O35: 0 | P35: =SUM(D35:O35) -> -7418796.3 | Q35: المدفوعات لمستحقات الموظفين ( الرواتب, العمولات, الحوافز , الخ)
B36: Tax Payments | D36: -32047367 | E36: -34893488 | F36: -22077579 | G36: 0 | H36: 0 | I36: 0 | J36: 0 | K36: 0 | L36: 0 | M36: 0 | N36: 0 | O36: 0 | P36: =SUM(D36:O36) -> -89018434 | Q36: المدفوعات الضريبية بأنواعها
B37: Payments for Governmental Institutions | D37: -297713 | E37: -153630.12 | F37: -167734.87 | G37: 0 | H37: 0 | I37: 0 | J37: 0 | K37: 0 | L37: 0 | M37: 0 | N37: 0 | O37: 0 | P37: =SUM(D37:O37) -> -619077.99 | Q37: المدفوعات الحكومية بأنواعها
B38: Payments for Charity | D38: 0 | E38: 0 | F38: 0 | G38: 0 | H38: 0 | I38: 0 | J38: 0 | K38: 0 | L38: 0 | M38: 0 | N38: 0 | O38: 0 | P38: =SUM(D38:O38) -> 0 | Q38: المدفوعات الخيريه
B40: B) Cash from Investing Activities | Q40: ب) التدفقات النقدية من الأنشطة الإستثمارية
B41: Payments for Purchase of Fixed Assets and long term assets | D41: -18216 | E41: -23460 | F41: 0 | G41: 0 | H41: 0 | I41: 0 | J41: 0 | K41: 0 | L41: 0 | M41: 0 | N41: 0 | O41: 0 | P41: =SUM(D41:O41) -> -41676 | Q41: المدفوعات من أجل شراء الموجودات الثابتة أو أية إستثمارات طويلة الاجل
B42: Payments for Purchase of shares, securties and current/new investments | D42: -48875776 | E42: -9379000 | F42: -5335306.4 | G42: 0 | H42: 0 | I42: 0 | J42: 0 | K42: 0 | L42: 0 | M42: 0 | N42: 0 | O42: 0 | P42: =SUM(D42:O42) -> -63590082 | Q42: المدفوعات لشراء اسهم أو سندات أو الدخول في استثمارات جديدة
B44: C) Cash from Financing Activities | Q44: س) التدفقات النقدية من الأنشطة التمويلية
B45: Payments for Murabaha Loans | D45: 0 | E45: 0 | F45: 0 | G45: 0 | H45: 0 | I45: 0 | J45: 0 | K45: 0 | L45: 0 | M45: 0 | N45: 0 | O45: 0 | P45: =SUM(D45:O45) -> 0 | Q45: المدفوعات لسداد قروض المرابحه
B46: Dividend Payments | D46: -6795810 | E46: 0 | J46: 0 | L46: 0 | M46: 0 | P46: =SUM(D46:O46) -> -6795810 | Q46: المدفوعات الخاصة في توزيع الأرباح السنوية على الشركاء
B47: Payments for Shareholders | D47: 49996470 | E47: -779085.82 | F47: 700959.68 | G47: 0 | H47: 0 | I47: 0 | J47: 0 | K47: 0 | L47: 0 | M47: 0 | N47: 0 | O47: 0 | P47: =SUM(D47:O47) -> 49918344 | Q47: المدفوعات التي تتم على حسابات الشركاء الجارية لدى الشركة
B48: Payment for the Exit Partners | D48: -32200000 | E48: 0 | F48: -30000000 | G48: 0 | H48: 0 | I48: 0 | J48: 0 | M48: 0 | P48: =SUM(D48:O48) -> -62200000 | Q48: المدفوعات التى تتم على تخارج الشركاء
B49: D) Payments for Related-Affiliated Parties | D49: =-(13594955+440329248) -> -453924203 | E49: =-(47151012.05+151621875.45) -> -1.9877289e+08 | F49: =-(14933471.98+296209920.53) -> -3.1114339e+08 | G49: 0 | H49: 0 | I49: 0 | J49: 0 | K49: 0 | L49: 0 | M49: 0 | N49: 0 | O49: 0 | P49: =SUM(D49:O49) -> -9.6384048e+08 | Q49: د) المدفوعات الى الشركات الشقيقة التابعه
B51: Total Cash OutFlow | D51: =SUM(D34:D50) -> -547017594 | E51: =SUM(E34:E50) -> -2.5341319e+08 | F51: =SUM(F34:F50) -> -3.8404438e+08 | G51: =SUM(G34:G50) -> 0 | H51: =SUM(H34:H50) -> 0 | I51: =SUM(I34:I50) -> 0 | J51: =SUM(J34:J50) -> 0 | K51: =SUM(K34:K50) -> 0 | ... P51: =SUM(P34:P50) -> -1.1844752e+09 | Q51: اجمالي التدفقات النقدية الصادرة:
...
